[I 2022-05-03 19:44:21.239 ServerApp] jupyterlab | extension was successfully linked.
[I 2022-05-03 19:44:21.257 ServerApp] nbclassic | extension was successfully linked.
[I 2022-05-03 19:44:22.073 ServerApp] notebook_shim | extension was successfully linked.
[I 2022-05-03 19:44:22.074 ServerApp] panel.io.jupyter_server_extension | extension was successfully linked.
[I 2022-05-03 19:44:22.127 ServerApp] notebook_shim | extension was successfully loaded.
[I 2022-05-03 19:44:22.130 LabApp] JupyterLab extension loaded from /home/k/kimpson/bin/conda/envs/workhorse/lib/python3.7/site-packages/jupyterlab
[I 2022-05-03 19:44:22.130 LabApp] JupyterLab application directory is /home/k/kimpson/bin/conda/envs/workhorse/share/jupyter/lab
[I 2022-05-03 19:44:22.142 ServerApp] jupyterlab | extension was successfully loaded.
[I 2022-05-03 19:44:22.156 ServerApp] nbclassic | extension was successfully loaded.
[I 2022-05-03 19:44:22.159 ServerApp] panel.io.jupyter_server_extension | extension was successfully loaded.
[I 2022-05-03 19:44:22.167 ServerApp] Serving notebooks from local directory: /network/aopp/chaos/pred/kimpson/ML4L
[I 2022-05-03 19:44:22.169 ServerApp] Jupyter Server 1.15.6 is running at:
[I 2022-05-03 19:44:22.169 ServerApp] http://localhost:9168/lab
[I 2022-05-03 19:44:22.169 ServerApp]  or http://127.0.0.1:9168/lab
[I 2022-05-03 19:44:22.169 ServerApp] Use Control-C to stop this server and shut down all kernels (twice to skip confirmation).
[I 2022-05-03 19:46:42.667 LabApp] Build is up to date
[W 2022-05-03 19:46:49.774 ServerApp] Notebook reproducible_workflow/experiments/2. Lakes_with_extra_fields.ipynb is not trusted
[I 2022-05-03 19:46:56.821 ServerApp] Kernel started: 2410133d-412e-4c07-a9c5-000553d4eac0
[I 2022-05-03 19:51:05.148 ServerApp] Saving file at /reproducible_workflow/experiments/2. Lakes_with_extra_fields.ipynb
[W 2022-05-03 19:51:05.155 ServerApp] Notebook reproducible_workflow/experiments/2. Lakes_with_extra_fields.ipynb is not trusted
[I 2022-05-03 19:53:15.929 ServerApp] Saving file at /reproducible_workflow/experiments/2. Lakes_with_extra_fields.ipynb
[W 2022-05-03 19:53:15.933 ServerApp] Notebook reproducible_workflow/experiments/2. Lakes_with_extra_fields.ipynb is not trusted
[I 2022-05-03 19:55:26.761 ServerApp] Saving file at /reproducible_workflow/experiments/2. Lakes_with_extra_fields.ipynb
[W 2022-05-03 19:55:26.764 ServerApp] Notebook reproducible_workflow/experiments/2. Lakes_with_extra_fields.ipynb is not trusted
[I 2022-05-03 19:57:37.773 ServerApp] Saving file at /reproducible_workflow/experiments/2. Lakes_with_extra_fields.ipynb
[W 2022-05-03 19:57:37.776 ServerApp] Notebook reproducible_workflow/experiments/2. Lakes_with_extra_fields.ipynb is not trusted
[I 2022-05-03 19:59:49.312 ServerApp] Saving file at /reproducible_workflow/experiments/2. Lakes_with_extra_fields.ipynb
[W 2022-05-03 19:59:49.316 ServerApp] Notebook reproducible_workflow/experiments/2. Lakes_with_extra_fields.ipynb is not trusted
[I 2022-05-03 20:02:00.347 ServerApp] Saving file at /reproducible_workflow/experiments/2. Lakes_with_extra_fields.ipynb
[W 2022-05-03 20:02:00.350 ServerApp] Notebook reproducible_workflow/experiments/2. Lakes_with_extra_fields.ipynb is not trusted
[I 2022-05-03 20:04:12.461 ServerApp] Saving file at /reproducible_workflow/experiments/2. Lakes_with_extra_fields.ipynb
[W 2022-05-03 20:04:12.464 ServerApp] Notebook reproducible_workflow/experiments/2. Lakes_with_extra_fields.ipynb is not trusted
[E 2022-05-03 20:06:18.334 ServerApp] Uncaught exception in write_error
    Traceback (most recent call last):
      File "/home/k/kimpson/bin/conda/envs/workhorse/lib/python3.7/site-packages/tornado/web.py", line 1704, in _execute
      File "/home/k/kimpson/bin/conda/envs/workhorse/lib/python3.7/site-packages/tornado/web.py", line 2576, in get
      File "/home/k/kimpson/bin/conda/envs/workhorse/lib/python3.7/site-packages/jupyter_server/base/handlers.py", line 872, in validate_absolute_path
      File "/home/k/kimpson/bin/conda/envs/workhorse/lib/python3.7/site-packages/tornado/web.py", line 2778, in validate_absolute_path
    tornado.web.HTTPError: HTTP 404: Not Found
    
    During handling of the above exception, another exception occurred:
    
    Traceback (most recent call last):
      File "/home/k/kimpson/bin/conda/envs/workhorse/lib/python3.7/site-packages/jupyter_server/base/handlers.py", line 595, in write_error
      File "/home/k/kimpson/bin/conda/envs/workhorse/lib/python3.7/site-packages/jupyter_server/base/handlers.py", line 525, in render_template
      File "/home/k/kimpson/bin/conda/envs/workhorse/lib/python3.7/site-packages/jupyter_server/base/handlers.py", line 521, in get_template
      File "/home/k/kimpson/bin/conda/envs/workhorse/lib/python3.7/site-packages/jinja2/environment.py", line 997, in get_template
      File "/home/k/kimpson/bin/conda/envs/workhorse/lib/python3.7/site-packages/jinja2/environment.py", line 958, in _load_template
      File "/home/k/kimpson/bin/conda/envs/workhorse/lib/python3.7/site-packages/jinja2/loaders.py", line 125, in load
      File "/home/k/kimpson/bin/conda/envs/workhorse/lib/python3.7/site-packages/jinja2/loaders.py", line 214, in get_source
    jinja2.exceptions.TemplateNotFound: 404.html
    
    During handling of the above exception, another exception occurred:
    
    Traceback (most recent call last):
      File "/home/k/kimpson/bin/conda/envs/workhorse/lib/python3.7/site-packages/tornado/web.py", line 1217, in send_error
      File "/home/k/kimpson/bin/conda/envs/workhorse/lib/python3.7/site-packages/jupyter_server/base/handlers.py", line 597, in write_error
      File "/home/k/kimpson/bin/conda/envs/workhorse/lib/python3.7/site-packages/jupyter_server/base/handlers.py", line 525, in render_template
      File "/home/k/kimpson/bin/conda/envs/workhorse/lib/python3.7/site-packages/jupyter_server/base/handlers.py", line 521, in get_template
      File "/home/k/kimpson/bin/conda/envs/workhorse/lib/python3.7/site-packages/jinja2/environment.py", line 997, in get_template
      File "/home/k/kimpson/bin/conda/envs/workhorse/lib/python3.7/site-packages/jinja2/environment.py", line 958, in _load_template
      File "/home/k/kimpson/bin/conda/envs/workhorse/lib/python3.7/site-packages/jinja2/loaders.py", line 125, in load
      File "/home/k/kimpson/bin/conda/envs/workhorse/lib/python3.7/site-packages/jinja2/loaders.py", line 214, in get_source
    jinja2.exceptions.TemplateNotFound: error.html
[W 2022-05-03 20:06:18.388 ServerApp] 404 GET /static/favicons/favicon-busy-1.ico (::1) 66.41ms referer=http://localhost:8881/lab/tree/reproducible_workflow/experiments/2.%20Lakes_with_extra_fields.ipynb
[E 2022-05-03 20:06:18.400 ServerApp] Uncaught exception in write_error
    Traceback (most recent call last):
      File "/home/k/kimpson/bin/conda/envs/workhorse/lib/python3.7/site-packages/tornado/web.py", line 1704, in _execute
      File "/home/k/kimpson/bin/conda/envs/workhorse/lib/python3.7/site-packages/tornado/web.py", line 2576, in get
      File "/home/k/kimpson/bin/conda/envs/workhorse/lib/python3.7/site-packages/jupyter_server/base/handlers.py", line 872, in validate_absolute_path
      File "/home/k/kimpson/bin/conda/envs/workhorse/lib/python3.7/site-packages/tornado/web.py", line 2778, in validate_absolute_path
    tornado.web.HTTPError: HTTP 404: Not Found
    
    During handling of the above exception, another exception occurred:
    
    Traceback (most recent call last):
      File "/home/k/kimpson/bin/conda/envs/workhorse/lib/python3.7/site-packages/jupyter_server/base/handlers.py", line 595, in write_error
      File "/home/k/kimpson/bin/conda/envs/workhorse/lib/python3.7/site-packages/jupyter_server/base/handlers.py", line 525, in render_template
      File "/home/k/kimpson/bin/conda/envs/workhorse/lib/python3.7/site-packages/jupyter_server/base/handlers.py", line 521, in get_template
      File "/home/k/kimpson/bin/conda/envs/workhorse/lib/python3.7/site-packages/jinja2/environment.py", line 997, in get_template
      File "/home/k/kimpson/bin/conda/envs/workhorse/lib/python3.7/site-packages/jinja2/environment.py", line 958, in _load_template
      File "/home/k/kimpson/bin/conda/envs/workhorse/lib/python3.7/site-packages/jinja2/loaders.py", line 125, in load
      File "/home/k/kimpson/bin/conda/envs/workhorse/lib/python3.7/site-packages/jinja2/loaders.py", line 214, in get_source
    jinja2.exceptions.TemplateNotFound: 404.html
    
    During handling of the above exception, another exception occurred:
    
    Traceback (most recent call last):
      File "/home/k/kimpson/bin/conda/envs/workhorse/lib/python3.7/site-packages/tornado/web.py", line 1217, in send_error
      File "/home/k/kimpson/bin/conda/envs/workhorse/lib/python3.7/site-packages/jupyter_server/base/handlers.py", line 597, in write_error
      File "/home/k/kimpson/bin/conda/envs/workhorse/lib/python3.7/site-packages/jupyter_server/base/handlers.py", line 525, in render_template
      File "/home/k/kimpson/bin/conda/envs/workhorse/lib/python3.7/site-packages/jupyter_server/base/handlers.py", line 521, in get_template
      File "/home/k/kimpson/bin/conda/envs/workhorse/lib/python3.7/site-packages/jinja2/environment.py", line 997, in get_template
      File "/home/k/kimpson/bin/conda/envs/workhorse/lib/python3.7/site-packages/jinja2/environment.py", line 958, in _load_template
      File "/home/k/kimpson/bin/conda/envs/workhorse/lib/python3.7/site-packages/jinja2/loaders.py", line 125, in load
      File "/home/k/kimpson/bin/conda/envs/workhorse/lib/python3.7/site-packages/jinja2/loaders.py", line 214, in get_source
    jinja2.exceptions.TemplateNotFound: error.html
[W 2022-05-03 20:06:18.452 ServerApp] 404 GET /static/favicons/favicon.ico (::1) 61.28ms referer=http://localhost:8881/lab/tree/reproducible_workflow/experiments/2.%20Lakes_with_extra_fields.ipynb
[I 2022-05-03 20:06:24.267 ServerApp] Saving file at /reproducible_workflow/experiments/2. Lakes_with_extra_fields.ipynb
[W 2022-05-03 20:06:24.270 ServerApp] Notebook reproducible_workflow/experiments/2. Lakes_with_extra_fields.ipynb is not trusted
[E 2022-05-03 20:06:46.275 ServerApp] Uncaught exception in write_error
    Traceback (most recent call last):
      File "/home/k/kimpson/bin/conda/envs/workhorse/lib/python3.7/site-packages/tornado/web.py", line 1704, in _execute
      File "/home/k/kimpson/bin/conda/envs/workhorse/lib/python3.7/site-packages/tornado/web.py", line 2576, in get
      File "/home/k/kimpson/bin/conda/envs/workhorse/lib/python3.7/site-packages/jupyter_server/base/handlers.py", line 872, in validate_absolute_path
      File "/home/k/kimpson/bin/conda/envs/workhorse/lib/python3.7/site-packages/tornado/web.py", line 2778, in validate_absolute_path
    tornado.web.HTTPError: HTTP 404: Not Found
    
    During handling of the above exception, another exception occurred:
    
    Traceback (most recent call last):
      File "/home/k/kimpson/bin/conda/envs/workhorse/lib/python3.7/site-packages/jupyter_server/base/handlers.py", line 595, in write_error
      File "/home/k/kimpson/bin/conda/envs/workhorse/lib/python3.7/site-packages/jupyter_server/base/handlers.py", line 525, in render_template
      File "/home/k/kimpson/bin/conda/envs/workhorse/lib/python3.7/site-packages/jupyter_server/base/handlers.py", line 521, in get_template
      File "/home/k/kimpson/bin/conda/envs/workhorse/lib/python3.7/site-packages/jinja2/environment.py", line 997, in get_template
      File "/home/k/kimpson/bin/conda/envs/workhorse/lib/python3.7/site-packages/jinja2/environment.py", line 958, in _load_template
      File "/home/k/kimpson/bin/conda/envs/workhorse/lib/python3.7/site-packages/jinja2/loaders.py", line 125, in load
      File "/home/k/kimpson/bin/conda/envs/workhorse/lib/python3.7/site-packages/jinja2/loaders.py", line 214, in get_source
    jinja2.exceptions.TemplateNotFound: 404.html
    
    During handling of the above exception, another exception occurred:
    
    Traceback (most recent call last):
      File "/home/k/kimpson/bin/conda/envs/workhorse/lib/python3.7/site-packages/tornado/web.py", line 1217, in send_error
      File "/home/k/kimpson/bin/conda/envs/workhorse/lib/python3.7/site-packages/jupyter_server/base/handlers.py", line 597, in write_error
      File "/home/k/kimpson/bin/conda/envs/workhorse/lib/python3.7/site-packages/jupyter_server/base/handlers.py", line 525, in render_template
      File "/home/k/kimpson/bin/conda/envs/workhorse/lib/python3.7/site-packages/jupyter_server/base/handlers.py", line 521, in get_template
      File "/home/k/kimpson/bin/conda/envs/workhorse/lib/python3.7/site-packages/jinja2/environment.py", line 997, in get_template
      File "/home/k/kimpson/bin/conda/envs/workhorse/lib/python3.7/site-packages/jinja2/environment.py", line 958, in _load_template
      File "/home/k/kimpson/bin/conda/envs/workhorse/lib/python3.7/site-packages/jinja2/loaders.py", line 125, in load
      File "/home/k/kimpson/bin/conda/envs/workhorse/lib/python3.7/site-packages/jinja2/loaders.py", line 214, in get_source
    jinja2.exceptions.TemplateNotFound: error.html
[W 2022-05-03 20:06:46.324 ServerApp] 404 GET /static/favicons/favicon-busy-1.ico (::1) 59.33ms referer=http://localhost:8881/lab/tree/reproducible_workflow/experiments/2.%20Lakes_with_extra_fields.ipynb
[I 2022-05-03 20:07:06.784 ServerApp] Saving file at /reproducible_workflow/experiments/2. Lakes_with_extra_fields.ipynb
[W 2022-05-03 20:07:06.786 ServerApp] Notebook reproducible_workflow/experiments/2. Lakes_with_extra_fields.ipynb is not trusted
[E 2022-05-03 20:07:17.262 ServerApp] [Errno 13] Permission denied: '/home/k/kimpson/.local/share/jupyter/runtime/kernel-2410133d-412e-4c07-a9c5-000553d4eac0.json'
    Traceback (most recent call last):
      File "/home/k/kimpson/bin/conda/envs/workhorse/lib/python3.7/site-packages/jupyter_client/manager.py", line 71, in wrapper
      File "/home/k/kimpson/bin/conda/envs/workhorse/lib/python3.7/site-packages/jupyter_client/manager.py", line 376, in _async_start_kernel
      File "/home/k/kimpson/bin/conda/envs/workhorse/lib/python3.7/site-packages/jupyter_client/utils.py", line 34, in ensure_async
      File "/home/k/kimpson/bin/conda/envs/workhorse/lib/python3.7/site-packages/jupyter_client/manager.py", line 342, in _async_pre_start_kernel
      File "/home/k/kimpson/bin/conda/envs/workhorse/lib/python3.7/site-packages/jupyter_client/provisioning/local_provisioner.py", line 165, in pre_launch
      File "/home/k/kimpson/bin/conda/envs/workhorse/lib/python3.7/site-packages/jupyter_client/connect.py", line 514, in write_connection_file
      File "/home/k/kimpson/bin/conda/envs/workhorse/lib/python3.7/site-packages/jupyter_client/connect.py", line 164, in write_connection_file
      File "/home/k/kimpson/bin/conda/envs/workhorse/lib/python3.7/contextlib.py", line 112, in __enter__
      File "/home/k/kimpson/bin/conda/envs/workhorse/lib/python3.7/site-packages/jupyter_core/paths.py", line 901, in secure_write
    PermissionError: [Errno 13] Permission denied: '/home/k/kimpson/.local/share/jupyter/runtime/kernel-2410133d-412e-4c07-a9c5-000553d4eac0.json'
[E 2022-05-03 20:07:17.288 ServerApp] Exception restarting kernel
    Traceback (most recent call last):
      File "/home/k/kimpson/bin/conda/envs/workhorse/lib/python3.7/site-packages/jupyter_server/services/kernels/handlers.py", line 96, in post
      File "/home/k/kimpson/bin/conda/envs/workhorse/lib/python3.7/site-packages/jupyter_server/services/kernels/kernelmanager.py", line 404, in restart_kernel
      File "/home/k/kimpson/bin/conda/envs/workhorse/lib/python3.7/site-packages/jupyter_server/utils.py", line 189, in ensure_async
      File "/home/k/kimpson/bin/conda/envs/workhorse/lib/python3.7/site-packages/jupyter_client/multikernelmanager.py", line 381, in _async_restart_kernel
      File "/home/k/kimpson/bin/conda/envs/workhorse/lib/python3.7/site-packages/jupyter_client/utils.py", line 34, in ensure_async
      File "/home/k/kimpson/bin/conda/envs/workhorse/lib/python3.7/site-packages/jupyter_client/manager.py", line 530, in _async_restart_kernel
      File "/home/k/kimpson/bin/conda/envs/workhorse/lib/python3.7/site-packages/jupyter_client/utils.py", line 34, in ensure_async
      File "/home/k/kimpson/bin/conda/envs/workhorse/lib/python3.7/site-packages/jupyter_client/manager.py", line 79, in wrapper
      File "/home/k/kimpson/bin/conda/envs/workhorse/lib/python3.7/site-packages/jupyter_client/manager.py", line 71, in wrapper
      File "/home/k/kimpson/bin/conda/envs/workhorse/lib/python3.7/site-packages/jupyter_client/manager.py", line 376, in _async_start_kernel
      File "/home/k/kimpson/bin/conda/envs/workhorse/lib/python3.7/site-packages/jupyter_client/utils.py", line 34, in ensure_async
      File "/home/k/kimpson/bin/conda/envs/workhorse/lib/python3.7/site-packages/jupyter_client/manager.py", line 342, in _async_pre_start_kernel
      File "/home/k/kimpson/bin/conda/envs/workhorse/lib/python3.7/site-packages/jupyter_client/provisioning/local_provisioner.py", line 165, in pre_launch
      File "/home/k/kimpson/bin/conda/envs/workhorse/lib/python3.7/site-packages/jupyter_client/connect.py", line 514, in write_connection_file
      File "/home/k/kimpson/bin/conda/envs/workhorse/lib/python3.7/site-packages/jupyter_client/connect.py", line 164, in write_connection_file
      File "/home/k/kimpson/bin/conda/envs/workhorse/lib/python3.7/contextlib.py", line 112, in __enter__
      File "/home/k/kimpson/bin/conda/envs/workhorse/lib/python3.7/site-packages/jupyter_core/paths.py", line 901, in secure_write
    PermissionError: [Errno 13] Permission denied: '/home/k/kimpson/.local/share/jupyter/runtime/kernel-2410133d-412e-4c07-a9c5-000553d4eac0.json'
[E 2022-05-03 20:07:17.381 ServerApp] {
      "Host": "localhost:8881",
      "Accept": "*/*",
      "Referer": "http://localhost:8881/lab/tree/reproducible_workflow/experiments/2.%20Lakes_with_extra_fields.ipynb",
      "User-Agent": "Mozilla/5.0 (Macintosh; Intel Mac OS X 10_15_7) AppleWebKit/537.36 (KHTML, like Gecko) Chrome/100.0.4896.79 Safari/537.36"
    }
[E 2022-05-03 20:07:17.382 ServerApp] 500 POST /api/kernels/2410133d-412e-4c07-a9c5-000553d4eac0/restart?1651604834595 (::1) 2742.14ms referer=http://localhost:8881/lab/tree/reproducible_workflow/experiments/2.%20Lakes_with_extra_fields.ipynb
[I 2022-05-03 20:07:50.762 ServerApp] Kernel interrupted: 2410133d-412e-4c07-a9c5-000553d4eac0
[E 2022-05-03 20:07:50.763 ServerApp] Uncaught exception POST /api/kernels/2410133d-412e-4c07-a9c5-000553d4eac0/interrupt?1651604870723 (::1)
    HTTPServerRequest(protocol='http', host='localhost:8881', method='POST', uri='/api/kernels/2410133d-412e-4c07-a9c5-000553d4eac0/interrupt?1651604870723', version='HTTP/1.1', remote_ip='::1')
    Traceback (most recent call last):
      File "/home/k/kimpson/bin/conda/envs/workhorse/lib/python3.7/site-packages/tornado/web.py", line 1704, in _execute
      File "/home/k/kimpson/bin/conda/envs/workhorse/lib/python3.7/site-packages/jupyter_server/services/kernels/handlers.py", line 91, in post
      File "/home/k/kimpson/bin/conda/envs/workhorse/lib/python3.7/site-packages/jupyter_server/utils.py", line 189, in ensure_async
      File "/home/k/kimpson/bin/conda/envs/workhorse/lib/python3.7/site-packages/jupyter_client/manager.py", line 587, in _async_interrupt_kernel
    RuntimeError: Cannot interrupt kernel. No kernel is running!
[W 2022-05-03 20:07:50.787 ServerApp] Unhandled error
[E 2022-05-03 20:07:50.788 ServerApp] {
      "Host": "localhost:8881",
      "Accept": "*/*",
      "Referer": "http://localhost:8881/lab/tree/reproducible_workflow/experiments/2.%20Lakes_with_extra_fields.ipynb",
      "User-Agent": "Mozilla/5.0 (Macintosh; Intel Mac OS X 10_15_7) AppleWebKit/537.36 (KHTML, like Gecko) Chrome/100.0.4896.79 Safari/537.36"
    }
[E 2022-05-03 20:07:50.788 ServerApp] 500 POST /api/kernels/2410133d-412e-4c07-a9c5-000553d4eac0/interrupt?1651604870723 (::1) 26.77ms referer=http://localhost:8881/lab/tree/reproducible_workflow/experiments/2.%20Lakes_with_extra_fields.ipynb
[I 2022-05-03 20:07:51.111 ServerApp] Kernel interrupted: 2410133d-412e-4c07-a9c5-000553d4eac0
[E 2022-05-03 20:07:51.111 ServerApp] Uncaught exception POST /api/kernels/2410133d-412e-4c07-a9c5-000553d4eac0/interrupt?1651604871073 (::1)
    HTTPServerRequest(protocol='http', host='localhost:8881', method='POST', uri='/api/kernels/2410133d-412e-4c07-a9c5-000553d4eac0/interrupt?1651604871073', version='HTTP/1.1', remote_ip='::1')
    Traceback (most recent call last):
      File "/home/k/kimpson/bin/conda/envs/workhorse/lib/python3.7/site-packages/tornado/web.py", line 1704, in _execute
      File "/home/k/kimpson/bin/conda/envs/workhorse/lib/python3.7/site-packages/jupyter_server/services/kernels/handlers.py", line 91, in post
      File "/home/k/kimpson/bin/conda/envs/workhorse/lib/python3.7/site-packages/jupyter_server/utils.py", line 189, in ensure_async
      File "/home/k/kimpson/bin/conda/envs/workhorse/lib/python3.7/site-packages/jupyter_client/manager.py", line 587, in _async_interrupt_kernel
    RuntimeError: Cannot interrupt kernel. No kernel is running!
[W 2022-05-03 20:07:51.134 ServerApp] Unhandled error
[E 2022-05-03 20:07:51.134 ServerApp] {
      "Host": "localhost:8881",
      "Accept": "*/*",
      "Referer": "http://localhost:8881/lab/tree/reproducible_workflow/experiments/2.%20Lakes_with_extra_fields.ipynb",
      "User-Agent": "Mozilla/5.0 (Macintosh; Intel Mac OS X 10_15_7) AppleWebKit/537.36 (KHTML, like Gecko) Chrome/100.0.4896.79 Safari/537.36"
    }
[E 2022-05-03 20:07:51.135 ServerApp] 500 POST /api/kernels/2410133d-412e-4c07-a9c5-000553d4eac0/interrupt?1651604871073 (::1) 25.18ms referer=http://localhost:8881/lab/tree/reproducible_workflow/experiments/2.%20Lakes_with_extra_fields.ipynb
[I 2022-05-03 20:07:51.249 ServerApp] Kernel interrupted: 2410133d-412e-4c07-a9c5-000553d4eac0
[E 2022-05-03 20:07:51.249 ServerApp] Uncaught exception POST /api/kernels/2410133d-412e-4c07-a9c5-000553d4eac0/interrupt?1651604871212 (::1)
    HTTPServerRequest(protocol='http', host='localhost:8881', method='POST', uri='/api/kernels/2410133d-412e-4c07-a9c5-000553d4eac0/interrupt?1651604871212', version='HTTP/1.1', remote_ip='::1')
    Traceback (most recent call last):
      File "/home/k/kimpson/bin/conda/envs/workhorse/lib/python3.7/site-packages/tornado/web.py", line 1704, in _execute
      File "/home/k/kimpson/bin/conda/envs/workhorse/lib/python3.7/site-packages/jupyter_server/services/kernels/handlers.py", line 91, in post
      File "/home/k/kimpson/bin/conda/envs/workhorse/lib/python3.7/site-packages/jupyter_server/utils.py", line 189, in ensure_async
      File "/home/k/kimpson/bin/conda/envs/workhorse/lib/python3.7/site-packages/jupyter_client/manager.py", line 587, in _async_interrupt_kernel
    RuntimeError: Cannot interrupt kernel. No kernel is running!
[W 2022-05-03 20:07:51.272 ServerApp] Unhandled error
[E 2022-05-03 20:07:51.273 ServerApp] {
      "Host": "localhost:8881",
      "Accept": "*/*",
      "Referer": "http://localhost:8881/lab/tree/reproducible_workflow/experiments/2.%20Lakes_with_extra_fields.ipynb",
      "User-Agent": "Mozilla/5.0 (Macintosh; Intel Mac OS X 10_15_7) AppleWebKit/537.36 (KHTML, like Gecko) Chrome/100.0.4896.79 Safari/537.36"
    }
[E 2022-05-03 20:07:51.273 ServerApp] 500 POST /api/kernels/2410133d-412e-4c07-a9c5-000553d4eac0/interrupt?1651604871212 (::1) 25.01ms referer=http://localhost:8881/lab/tree/reproducible_workflow/experiments/2.%20Lakes_with_extra_fields.ipynb
[I 2022-05-03 20:07:51.381 ServerApp] Kernel interrupted: 2410133d-412e-4c07-a9c5-000553d4eac0
[E 2022-05-03 20:07:51.381 ServerApp] Uncaught exception POST /api/kernels/2410133d-412e-4c07-a9c5-000553d4eac0/interrupt?1651604871343 (::1)
    HTTPServerRequest(protocol='http', host='localhost:8881', method='POST', uri='/api/kernels/2410133d-412e-4c07-a9c5-000553d4eac0/interrupt?1651604871343', version='HTTP/1.1', remote_ip='::1')
    Traceback (most recent call last):
      File "/home/k/kimpson/bin/conda/envs/workhorse/lib/python3.7/site-packages/tornado/web.py", line 1704, in _execute
      File "/home/k/kimpson/bin/conda/envs/workhorse/lib/python3.7/site-packages/jupyter_server/services/kernels/handlers.py", line 91, in post
      File "/home/k/kimpson/bin/conda/envs/workhorse/lib/python3.7/site-packages/jupyter_server/utils.py", line 189, in ensure_async
      File "/home/k/kimpson/bin/conda/envs/workhorse/lib/python3.7/site-packages/jupyter_client/manager.py", line 587, in _async_interrupt_kernel
    RuntimeError: Cannot interrupt kernel. No kernel is running!
[W 2022-05-03 20:07:51.404 ServerApp] Unhandled error
[E 2022-05-03 20:07:51.404 ServerApp] {
      "Host": "localhost:8881",
      "Accept": "*/*",
      "Referer": "http://localhost:8881/lab/tree/reproducible_workflow/experiments/2.%20Lakes_with_extra_fields.ipynb",
      "User-Agent": "Mozilla/5.0 (Macintosh; Intel Mac OS X 10_15_7) AppleWebKit/537.36 (KHTML, like Gecko) Chrome/100.0.4896.79 Safari/537.36"
    }
[E 2022-05-03 20:07:51.405 ServerApp] 500 POST /api/kernels/2410133d-412e-4c07-a9c5-000553d4eac0/interrupt?1651604871343 (::1) 24.69ms referer=http://localhost:8881/lab/tree/reproducible_workflow/experiments/2.%20Lakes_with_extra_fields.ipynb
[I 2022-05-03 20:07:51.509 ServerApp] Kernel interrupted: 2410133d-412e-4c07-a9c5-000553d4eac0
[E 2022-05-03 20:07:51.510 ServerApp] Uncaught exception POST /api/kernels/2410133d-412e-4c07-a9c5-000553d4eac0/interrupt?1651604871472 (::1)
    HTTPServerRequest(protocol='http', host='localhost:8881', method='POST', uri='/api/kernels/2410133d-412e-4c07-a9c5-000553d4eac0/interrupt?1651604871472', version='HTTP/1.1', remote_ip='::1')
    Traceback (most recent call last):
      File "/home/k/kimpson/bin/conda/envs/workhorse/lib/python3.7/site-packages/tornado/web.py", line 1704, in _execute
      File "/home/k/kimpson/bin/conda/envs/workhorse/lib/python3.7/site-packages/jupyter_server/services/kernels/handlers.py", line 91, in post
      File "/home/k/kimpson/bin/conda/envs/workhorse/lib/python3.7/site-packages/jupyter_server/utils.py", line 189, in ensure_async
      File "/home/k/kimpson/bin/conda/envs/workhorse/lib/python3.7/site-packages/jupyter_client/manager.py", line 587, in _async_interrupt_kernel
    RuntimeError: Cannot interrupt kernel. No kernel is running!
[W 2022-05-03 20:07:51.531 ServerApp] Unhandled error
[E 2022-05-03 20:07:51.532 ServerApp] {
      "Host": "localhost:8881",
      "Accept": "*/*",
      "Referer": "http://localhost:8881/lab/tree/reproducible_workflow/experiments/2.%20Lakes_with_extra_fields.ipynb",
      "User-Agent": "Mozilla/5.0 (Macintosh; Intel Mac OS X 10_15_7) AppleWebKit/537.36 (KHTML, like Gecko) Chrome/100.0.4896.79 Safari/537.36"
    }
[E 2022-05-03 20:07:51.532 ServerApp] 500 POST /api/kernels/2410133d-412e-4c07-a9c5-000553d4eac0/interrupt?1651604871472 (::1) 23.83ms referer=http://localhost:8881/lab/tree/reproducible_workflow/experiments/2.%20Lakes_with_extra_fields.ipynb
[I 2022-05-03 20:07:51.654 ServerApp] Kernel interrupted: 2410133d-412e-4c07-a9c5-000553d4eac0
[E 2022-05-03 20:07:51.654 ServerApp] Uncaught exception POST /api/kernels/2410133d-412e-4c07-a9c5-000553d4eac0/interrupt?1651604871616 (::1)
    HTTPServerRequest(protocol='http', host='localhost:8881', method='POST', uri='/api/kernels/2410133d-412e-4c07-a9c5-000553d4eac0/interrupt?1651604871616', version='HTTP/1.1', remote_ip='::1')
    Traceback (most recent call last):
      File "/home/k/kimpson/bin/conda/envs/workhorse/lib/python3.7/site-packages/tornado/web.py", line 1704, in _execute
      File "/home/k/kimpson/bin/conda/envs/workhorse/lib/python3.7/site-packages/jupyter_server/services/kernels/handlers.py", line 91, in post
      File "/home/k/kimpson/bin/conda/envs/workhorse/lib/python3.7/site-packages/jupyter_server/utils.py", line 189, in ensure_async
      File "/home/k/kimpson/bin/conda/envs/workhorse/lib/python3.7/site-packages/jupyter_client/manager.py", line 587, in _async_interrupt_kernel
    RuntimeError: Cannot interrupt kernel. No kernel is running!
[W 2022-05-03 20:07:51.676 ServerApp] Unhandled error
[E 2022-05-03 20:07:51.676 ServerApp] {
      "Host": "localhost:8881",
      "Accept": "*/*",
      "Referer": "http://localhost:8881/lab/tree/reproducible_workflow/experiments/2.%20Lakes_with_extra_fields.ipynb",
      "User-Agent": "Mozilla/5.0 (Macintosh; Intel Mac OS X 10_15_7) AppleWebKit/537.36 (KHTML, like Gecko) Chrome/100.0.4896.79 Safari/537.36"
    }
[E 2022-05-03 20:07:51.677 ServerApp] 500 POST /api/kernels/2410133d-412e-4c07-a9c5-000553d4eac0/interrupt?1651604871616 (::1) 23.54ms referer=http://localhost:8881/lab/tree/reproducible_workflow/experiments/2.%20Lakes_with_extra_fields.ipynb
[E 2022-05-03 20:07:55.653 ServerApp] Cannot interrupt kernel. No kernel is running!
    Traceback (most recent call last):
      File "/home/k/kimpson/bin/conda/envs/workhorse/lib/python3.7/site-packages/jupyter_client/manager.py", line 71, in wrapper
      File "/home/k/kimpson/bin/conda/envs/workhorse/lib/python3.7/site-packages/jupyter_client/manager.py", line 479, in _async_shutdown_kernel
      File "/home/k/kimpson/bin/conda/envs/workhorse/lib/python3.7/site-packages/jupyter_client/utils.py", line 34, in ensure_async
      File "/home/k/kimpson/bin/conda/envs/workhorse/lib/python3.7/site-packages/jupyter_client/manager.py", line 587, in _async_interrupt_kernel
    RuntimeError: Cannot interrupt kernel. No kernel is running!
[E 2022-05-03 20:07:55.666 ServerApp] Exception restarting kernel
    Traceback (most recent call last):
      File "/home/k/kimpson/bin/conda/envs/workhorse/lib/python3.7/site-packages/jupyter_server/services/kernels/handlers.py", line 96, in post
      File "/home/k/kimpson/bin/conda/envs/workhorse/lib/python3.7/site-packages/jupyter_server/services/kernels/kernelmanager.py", line 404, in restart_kernel
      File "/home/k/kimpson/bin/conda/envs/workhorse/lib/python3.7/site-packages/jupyter_server/utils.py", line 189, in ensure_async
      File "/home/k/kimpson/bin/conda/envs/workhorse/lib/python3.7/site-packages/jupyter_client/multikernelmanager.py", line 381, in _async_restart_kernel
      File "/home/k/kimpson/bin/conda/envs/workhorse/lib/python3.7/site-packages/jupyter_client/utils.py", line 34, in ensure_async
      File "/home/k/kimpson/bin/conda/envs/workhorse/lib/python3.7/site-packages/jupyter_client/manager.py", line 523, in _async_restart_kernel
      File "/home/k/kimpson/bin/conda/envs/workhorse/lib/python3.7/site-packages/jupyter_client/utils.py", line 34, in ensure_async
      File "/home/k/kimpson/bin/conda/envs/workhorse/lib/python3.7/site-packages/jupyter_client/manager.py", line 79, in wrapper
      File "/home/k/kimpson/bin/conda/envs/workhorse/lib/python3.7/site-packages/jupyter_client/manager.py", line 71, in wrapper
      File "/home/k/kimpson/bin/conda/envs/workhorse/lib/python3.7/site-packages/jupyter_client/manager.py", line 479, in _async_shutdown_kernel
      File "/home/k/kimpson/bin/conda/envs/workhorse/lib/python3.7/site-packages/jupyter_client/utils.py", line 34, in ensure_async
      File "/home/k/kimpson/bin/conda/envs/workhorse/lib/python3.7/site-packages/jupyter_client/manager.py", line 587, in _async_interrupt_kernel
    RuntimeError: Cannot interrupt kernel. No kernel is running!
[E 2022-05-03 20:07:55.732 ServerApp] {
      "Host": "localhost:8881",
      "Accept": "*/*",
      "Referer": "http://localhost:8881/lab/tree/reproducible_workflow/experiments/2.%20Lakes_with_extra_fields.ipynb",
      "User-Agent": "Mozilla/5.0 (Macintosh; Intel Mac OS X 10_15_7) AppleWebKit/537.36 (KHTML, like Gecko) Chrome/100.0.4896.79 Safari/537.36"
    }
[E 2022-05-03 20:07:55.732 ServerApp] 500 POST /api/kernels/2410133d-412e-4c07-a9c5-000553d4eac0/restart?1651604875603 (::1) 83.42ms referer=http://localhost:8881/lab/tree/reproducible_workflow/experiments/2.%20Lakes_with_extra_fields.ipynb
[I 2022-05-03 20:08:07.684 ServerApp] Starting buffering for 2410133d-412e-4c07-a9c5-000553d4eac0:b669652f-34fa-4a5c-9d97-ef324e8ceb62
[I 2022-05-03 20:08:10.493 ServerApp] 302 GET / (::1) 1.50ms
[E 2022-05-03 20:08:10.551 ServerApp] Uncaught exception GET /lab? (::1)
    HTTPServerRequest(protocol='http', host='localhost:8881', method='GET', uri='/lab?', version='HTTP/1.1', remote_ip='::1')
    Traceback (most recent call last):
      File "/home/k/kimpson/bin/conda/envs/workhorse/lib/python3.7/site-packages/jupyter_server/extension/handler.py", line 15, in get_template
      File "/home/k/kimpson/bin/conda/envs/workhorse/lib/python3.7/site-packages/jinja2/environment.py", line 997, in get_template
      File "/home/k/kimpson/bin/conda/envs/workhorse/lib/python3.7/site-packages/jinja2/environment.py", line 958, in _load_template
      File "/home/k/kimpson/bin/conda/envs/workhorse/lib/python3.7/site-packages/jinja2/loaders.py", line 125, in load
      File "/home/k/kimpson/bin/conda/envs/workhorse/lib/python3.7/site-packages/jinja2/loaders.py", line 214, in get_source
    jinja2.exceptions.TemplateNotFound: index.html
    
    During handling of the above exception, another exception occurred:
    
    Traceback (most recent call last):
      File "/home/k/kimpson/bin/conda/envs/workhorse/lib/python3.7/site-packages/tornado/web.py", line 1702, in _execute
      File "/home/k/kimpson/bin/conda/envs/workhorse/lib/python3.7/site-packages/tornado/web.py", line 3173, in wrapper
      File "/home/k/kimpson/bin/conda/envs/workhorse/lib/python3.7/site-packages/tornado/web.py", line 1878, in wrapper
      File "/home/k/kimpson/bin/conda/envs/workhorse/lib/python3.7/site-packages/jupyterlab_server/handlers.py", line 158, in get
      File "/home/k/kimpson/bin/conda/envs/workhorse/lib/python3.7/site-packages/jupyter_server/base/handlers.py", line 525, in render_template
      File "/home/k/kimpson/bin/conda/envs/workhorse/lib/python3.7/site-packages/jupyter_server/extension/handler.py", line 17, in get_template
      File "/home/k/kimpson/bin/conda/envs/workhorse/lib/python3.7/site-packages/jupyter_server/base/handlers.py", line 521, in get_template
      File "/home/k/kimpson/bin/conda/envs/workhorse/lib/python3.7/site-packages/jinja2/environment.py", line 997, in get_template
      File "/home/k/kimpson/bin/conda/envs/workhorse/lib/python3.7/site-packages/jinja2/environment.py", line 958, in _load_template
      File "/home/k/kimpson/bin/conda/envs/workhorse/lib/python3.7/site-packages/jinja2/loaders.py", line 125, in load
      File "/home/k/kimpson/bin/conda/envs/workhorse/lib/python3.7/site-packages/jinja2/loaders.py", line 214, in get_source
    jinja2.exceptions.TemplateNotFound: index.html
[E 2022-05-03 20:08:10.604 ServerApp] Uncaught exception in write_error
    Traceback (most recent call last):
      File "/home/k/kimpson/bin/conda/envs/workhorse/lib/python3.7/site-packages/jupyter_server/extension/handler.py", line 15, in get_template
      File "/home/k/kimpson/bin/conda/envs/workhorse/lib/python3.7/site-packages/jinja2/environment.py", line 997, in get_template
      File "/home/k/kimpson/bin/conda/envs/workhorse/lib/python3.7/site-packages/jinja2/environment.py", line 958, in _load_template
      File "/home/k/kimpson/bin/conda/envs/workhorse/lib/python3.7/site-packages/jinja2/loaders.py", line 125, in load
      File "/home/k/kimpson/bin/conda/envs/workhorse/lib/python3.7/site-packages/jinja2/loaders.py", line 214, in get_source
    jinja2.exceptions.TemplateNotFound: index.html
    
    During handling of the above exception, another exception occurred:
    
    Traceback (most recent call last):
      File "/home/k/kimpson/bin/conda/envs/workhorse/lib/python3.7/site-packages/tornado/web.py", line 1702, in _execute
      File "/home/k/kimpson/bin/conda/envs/workhorse/lib/python3.7/site-packages/tornado/web.py", line 3173, in wrapper
      File "/home/k/kimpson/bin/conda/envs/workhorse/lib/python3.7/site-packages/tornado/web.py", line 1878, in wrapper
      File "/home/k/kimpson/bin/conda/envs/workhorse/lib/python3.7/site-packages/jupyterlab_server/handlers.py", line 158, in get
      File "/home/k/kimpson/bin/conda/envs/workhorse/lib/python3.7/site-packages/jupyter_server/base/handlers.py", line 525, in render_template
      File "/home/k/kimpson/bin/conda/envs/workhorse/lib/python3.7/site-packages/jupyter_server/extension/handler.py", line 17, in get_template
      File "/home/k/kimpson/bin/conda/envs/workhorse/lib/python3.7/site-packages/jupyter_server/base/handlers.py", line 521, in get_template
      File "/home/k/kimpson/bin/conda/envs/workhorse/lib/python3.7/site-packages/jinja2/environment.py", line 997, in get_template
      File "/home/k/kimpson/bin/conda/envs/workhorse/lib/python3.7/site-packages/jinja2/environment.py", line 958, in _load_template
      File "/home/k/kimpson/bin/conda/envs/workhorse/lib/python3.7/site-packages/jinja2/loaders.py", line 125, in load
      File "/home/k/kimpson/bin/conda/envs/workhorse/lib/python3.7/site-packages/jinja2/loaders.py", line 214, in get_source
    jinja2.exceptions.TemplateNotFound: index.html
    
    During handling of the above exception, another exception occurred:
    
    Traceback (most recent call last):
      File "/home/k/kimpson/bin/conda/envs/workhorse/lib/python3.7/site-packages/jupyter_server/extension/handler.py", line 15, in get_template
      File "/home/k/kimpson/bin/conda/envs/workhorse/lib/python3.7/site-packages/jinja2/environment.py", line 997, in get_template
      File "/home/k/kimpson/bin/conda/envs/workhorse/lib/python3.7/site-packages/jinja2/environment.py", line 958, in _load_template
      File "/home/k/kimpson/bin/conda/envs/workhorse/lib/python3.7/site-packages/jinja2/loaders.py", line 125, in load
      File "/home/k/kimpson/bin/conda/envs/workhorse/lib/python3.7/site-packages/jinja2/loaders.py", line 214, in get_source
    jinja2.exceptions.TemplateNotFound: 500.html
    
    During handling of the above exception, another exception occurred:
    
    Traceback (most recent call last):
      File "/home/k/kimpson/bin/conda/envs/workhorse/lib/python3.7/site-packages/jupyter_server/base/handlers.py", line 595, in write_error
      File "/home/k/kimpson/bin/conda/envs/workhorse/lib/python3.7/site-packages/jupyter_server/base/handlers.py", line 525, in render_template
      File "/home/k/kimpson/bin/conda/envs/workhorse/lib/python3.7/site-packages/jupyter_server/extension/handler.py", line 17, in get_template
      File "/home/k/kimpson/bin/conda/envs/workhorse/lib/python3.7/site-packages/jupyter_server/base/handlers.py", line 521, in get_template
      File "/home/k/kimpson/bin/conda/envs/workhorse/lib/python3.7/site-packages/jinja2/environment.py", line 997, in get_template
      File "/home/k/kimpson/bin/conda/envs/workhorse/lib/python3.7/site-packages/jinja2/environment.py", line 958, in _load_template
      File "/home/k/kimpson/bin/conda/envs/workhorse/lib/python3.7/site-packages/jinja2/loaders.py", line 125, in load
      File "/home/k/kimpson/bin/conda/envs/workhorse/lib/python3.7/site-packages/jinja2/loaders.py", line 214, in get_source
    jinja2.exceptions.TemplateNotFound: 500.html
    
    During handling of the above exception, another exception occurred:
    
    Traceback (most recent call last):
      File "/home/k/kimpson/bin/conda/envs/workhorse/lib/python3.7/site-packages/jupyter_server/extension/handler.py", line 15, in get_template
      File "/home/k/kimpson/bin/conda/envs/workhorse/lib/python3.7/site-packages/jinja2/environment.py", line 997, in get_template
      File "/home/k/kimpson/bin/conda/envs/workhorse/lib/python3.7/site-packages/jinja2/environment.py", line 958, in _load_template
      File "/home/k/kimpson/bin/conda/envs/workhorse/lib/python3.7/site-packages/jinja2/loaders.py", line 125, in load
      File "/home/k/kimpson/bin/conda/envs/workhorse/lib/python3.7/site-packages/jinja2/loaders.py", line 214, in get_source
    jinja2.exceptions.TemplateNotFound: error.html
    
    During handling of the above exception, another exception occurred:
    
    Traceback (most recent call last):
      File "/home/k/kimpson/bin/conda/envs/workhorse/lib/python3.7/site-packages/tornado/web.py", line 1217, in send_error
      File "/home/k/kimpson/bin/conda/envs/workhorse/lib/python3.7/site-packages/jupyter_server/base/handlers.py", line 597, in write_error
      File "/home/k/kimpson/bin/conda/envs/workhorse/lib/python3.7/site-packages/jupyter_server/base/handlers.py", line 525, in render_template
      File "/home/k/kimpson/bin/conda/envs/workhorse/lib/python3.7/site-packages/jupyter_server/extension/handler.py", line 17, in get_template
      File "/home/k/kimpson/bin/conda/envs/workhorse/lib/python3.7/site-packages/jupyter_server/base/handlers.py", line 521, in get_template
      File "/home/k/kimpson/bin/conda/envs/workhorse/lib/python3.7/site-packages/jinja2/environment.py", line 997, in get_template
      File "/home/k/kimpson/bin/conda/envs/workhorse/lib/python3.7/site-packages/jinja2/environment.py", line 958, in _load_template
      File "/home/k/kimpson/bin/conda/envs/workhorse/lib/python3.7/site-packages/jinja2/loaders.py", line 125, in load
      File "/home/k/kimpson/bin/conda/envs/workhorse/lib/python3.7/site-packages/jinja2/loaders.py", line 214, in get_source
    jinja2.exceptions.TemplateNotFound: error.html
[E 2022-05-03 20:08:10.720 LabApp] {
      "Host": "localhost:8881",
      "Accept": "text/html,application/xhtml+xml,application/xml;q=0.9,image/avif,image/webp,image/apng,*/*;q=0.8,application/signed-exchange;v=b3;q=0.9",
      "User-Agent": "Mozilla/5.0 (Macintosh; Intel Mac OS X 10_15_7) AppleWebKit/537.36 (KHTML, like Gecko) Chrome/100.0.4896.79 Safari/537.36"
    }
[E 2022-05-03 20:08:10.721 LabApp] 500 GET /lab? (::1) 207.73ms referer=None
[I 2022-05-03 20:10:04.034 LabApp] Build is up to date
[W 2022-05-03 20:10:05.166 ServerApp] Notebook reproducible_workflow/experiments/2. Lakes_with_extra_fields.ipynb is not trusted
[W 2022-05-03 20:10:21.223 ServerApp] 500 GET /api/kernels/2410133d-412e-4c07-a9c5-000553d4eac0/channels?session_id=fbce5abd-edf5-4dcc-b1da-367fd71354d3 (::1): Cannot interrupt kernel. No kernel is running!
[E 2022-05-03 20:10:21.262 ServerApp] {
      "Host": "localhost:8881",
      "User-Agent": "Mozilla/5.0 (Macintosh; Intel Mac OS X 10_15_7) AppleWebKit/537.36 (KHTML, like Gecko) Chrome/100.0.4896.79 Safari/537.36"
    }
[E 2022-05-03 20:10:21.262 ServerApp] 500 GET /api/kernels/2410133d-412e-4c07-a9c5-000553d4eac0/channels?session_id=fbce5abd-edf5-4dcc-b1da-367fd71354d3 (::1) 43.43ms referer=None
[I 2022-05-03 20:11:34.483 ServerApp] 302 GET / (::1) 3.83ms
[I 2022-05-03 20:11:34.488 LabApp] 302 GET /lab (::1) 2.19ms
[C 2022-05-03 20:11:39.527 ServerApp] received signal 15, stopping
[I 2022-05-03 20:11:39.531 ServerApp] Shutting down 4 extensions
[I 2022-05-03 20:11:39.532 ServerApp] Shutting down 1 kernel
[I 2022-05-03 20:11:39.534 ServerApp] Kernel shutdown: 2410133d-412e-4c07-a9c5-000553d4eac0
[I 2022-05-03 20:11:39.534 ServerApp] Shutting down 0 terminals
/panel-preview/ /panel-preview
